Workbook
Name DebtFinancing: [2]筹资!$E$22

Sheet 图表 1 主要财务指标
A1: 603707.SH
A2: 45838
A3: 46203
F23: 营业收入 | G23: 营业成本 | H23: 销售费用 | I23: 管理费用 | J23: 研发费用 | K23: 财务费用 | L23: 所得税 | M23: 归母净利润 | N23: 扣非归母 净利润 | O23: 经营现金流
E24: 2025H1 | F24: 1979.85 | G24: 1237.68 | H24: 185.43 | I24: 117.58 | J24: 142.14 | K24: 46.98 | L24: 23.9 | M24: 286.27 | N24: 260.06 | O24: 410.41
E25: 2026H1 | F25: 1926.26 | G25: 1279.27 | H25: 203.91 | I25: 139.84 | J25: 119.31 | K25: 63.77 | L25: 2.39 | M25: 187.55 | N25: 146.29 | O25: 733.88
E26: 同比增速 | F26: =F25/F24-1 -> -0.027067707 | G26: =G25/G24-1 -> 0.033603193 | H26: =H25/H24-1 -> 0.099660249 | I26: =I25/I24-1 -> 0.18931791 | J26: =J25/J24-1 -> -0.16061629 | K26: =K25/K24-1 -> 0.35738612 | L26: =L25/L24-1 -> -0.9 | M26: =M25/M24-1 -> -0.34484927 | N26: =N25/N24-1 -> -0.43747597 | O26: =(O25-O24)/ABS(O24) -> 0.78816306

Sheet 图表2-3营业收入和归母净利润
A1: 603707.SH | K1: 45291 | L1: 45657 | M1: 46022 | N1: 46203 | O1: 45838
D2: 2016 | E2: 2017 | F2: 2018 | G2: 2019 | H2: 2020 | I2: 2021 | J2: 2022 | K2: 2023 | L2: 2024 | M2: 2025 | N2: 2026H1 | O2: 2025H1
C3: 营业收入 | D3: 581.91 | E3: 1112.73 | F3: 1700.33 | G3: 2469.67 | H3: 2914.88 | I3: 3686.69 | J3: 3712.7205 | K3: =[1]!s_stm07_is(A1,"W22161399",K1,1,1000000) -> 3931.3873 | L3: =[1]!s_stm07_is($A$1,"W22161399",L1,1,1000000) -> 3923.5858 | M3: =[1]!s_stm07_is($A$1,"W22161399",M1,1,1000000) -> 3990.678 | N3: 1926.26 | O3: 1980
C4: yoy | D4: 0.2415 | E4: =E3/D3-1 -> 0.91220292 | F4: =F3/E3-1 -> 0.5280706 | G4: =G3/F3-1 -> 0.45246511 | H4: =H3/G3-1 -> 0.18027105 | I4: =I3/H3-1 -> 0.26478277 | J4: =J3/I3-1 -> 0.0070606574 | K4: =K3/J3-1 -> 0.058896657 | L4: =L3/K3-1 -> -0.0019843978 | M4: =M3/L3-1 -> 0.017099713 | N4: =N3/O3-1 -> -0.027141414
C5: 归母净利润 | D5: 257.24 | E5: 314.22 | F5: 424.55 | G5: 604.96 | H5: 806.12 | I5: 1059.29 | J5: 1090.83 | K5: =[1]!s_stm07_is(A1,"W23021169",K1,1,1000000) -> -189.44579 | L5: =[1]!s_stm07_is($A$1,"W23021169",L1,1,1000000) -> 826.14487 | M5: =[1]!s_stm07_is($A$1,"W23021169",M1,1,1000000) -> 581.53615 | N5: 187.55 | O5: 286.27
C6: yoy | D6: 1.9381 | E6: =E5/D5-1 -> 0.22150521 | F6: =F5/E5-1 -> 0.35112342 | G6: =G5/F5-1 -> 0.42494406 | H6: =H5/G5-1 -> 0.33251785 | I6: =I5/H5-1 -> 0.31405994 | J6: =J5/I5-1 -> 0.02977466 | K6: =K5/J5-1 -> -1.1736712 | L6: =L5/K5-1 -> -5.360851 | M6: =M5/L5-1 -> -0.29608453 | N6: =N5/O5-1 -> -0.34484927

Sheet 图表4现金流量表
A1: 健友股份[603707.SH] - 现金流量表 | B1: 2016-06-30 | C1: 2016-09-30 | D1: 2016-12-31 | E1: 2017-03-31 | F1: 2017-06-30 | G1: 2017-09-30 | H1: 2017-12-31 | I1: 2018-03-31 | J1: 2018-06-30 | K1: 2018-09-30 | L1: 2018-12-31 | M1: 2019-03-31 | N1: 2019-06-30 | O1: 2019-09-30 | P1: 2019-12-31 | Q1: 2020-03-31 | R1: 2020-06-30 | S1: 2020-09-30 | T1: 2020-12-31 | U1: 2021-03-31 | V1: 2021H1
A2: 报告期 | B2: 2016H1 | C2: 2016Q3 | D2: 2016 | E2: 2017Q1 | F2: 2017H1 | G2: 2017Q3 | H2: 2017 | I2: 2018Q1 | J2: 2018H1 | K2: 2018Q3 | L2: 2018 | M2: 2019Q1 | N2: 2019H1 | O2: 2019Q3 | P2: 2019 | Q2: 2020Q1 | R2: 2020H1 | S2: 2020Q3 | T2: 2020 | U2: 2021Q1 | V2: 2021H1 | W2: 2021Q3 | X2: 2021 | Y2: 2022Q1 | Z2: 2022H1 | AA2: 2022Q3 | AB2: 2022 | AC2: 2023Q1 | AD2: 2023H1 | AE2: 2023Q3 | AF2: 2023 | AG2: 2024Q1 | AH2: 2024H1
A3: 报表类型 | B3: 合并报表 | C3: 合并报表 | D3: 合并报表 | E3: 合并报表 | F3: 合并报表 | G3: 合并报表 | H3: 合并报表 | I3: 合并报表 | J3: 合并报表 | K3: 合并报表 | L3: 合并报表 | M3: 合并报表 | N3: 合并报表 | O3: 合并报表 | P3: 合并报表 | Q3: 合并报表 | R3: 合并报表 | S3: 合并报表 | T3: 合并报表 | U3: 合并报表
A4: 经营活动产生的现金流量：
A5: 销售商品、提供劳务收到的现金 | B5: 294.25 | C5: 458.46 | D5: 564.35 | E5: 182.41 | F5: 372.12 | G5: 668.01 | H5: 988.6 | I5: 385.16 | J5: 894.62 | K5: 1399.96 | L5: 1616.42 | M5: 500.7 | N5: 1067.47 | O5: 1652.41 | P5: 2339.79 | Q5: 766.24 | R5: 1379.7 | S5: 2019.3 | T5: 2698.86 | U5: 900.94
A6: 收到的税费返还 | B6: 27.13 | C6: 87.41 | D6: 77.77 | E6: 28.23 | F6: 55.8 | G6: 92.74 | H6: 115.97 | I6: 58.12 | J6: 95.41 | K6: 121.56 | L6: 175.8 | M6: 52.93 | N6: 112.13 | O6: 159.37 | P6: 218.5 | Q6: 54.29 | R6: 104.09 | S6: 129.77 | T6: 151.68 | U6: 28.09
A7: 收到其他与经营活动有关的现金 | B7: 0.61 | C7: 1.25 | D7: 4.12 | E7: 0.49 | F7: 13.22 | G7: 21.99 | H7: 5.69 | I7: 1.52 | J7: 21.58 | K7: 29.96 | L7: 40.84 | M7: 4.69 | N7: 7.98 | O7: 26.77 | P7: 40.66 | Q7: 30.02 | R7: 26.64 | S7: 54.31 | T7: 63.6 | U7: 31.78
A8: 经营活动现金流入(金融类)
A9: 经营活动现金流入差额(特殊报表科目)
A10: 经营活动现金流入差额(合计平衡项目)
A11: 经营活动现金流入小计 | B11: 321.99 | C11: 547.12 | D11: 646.25 | E11: 211.13 | F11: 441.14 | G11: 782.74 | H11: 1110.26 | I11: 444.8 | J11: 1011.61 | K11: 1551.49 | L11: 1833.06 | M11: 558.32 | N11: 1187.58 | O11: 1838.55 | P11: 2598.95 | Q11: 850.56 | R11: 1510.44 | S11: 2203.38 | T11: 2914.14 | U11: 960.82
A12: 购买商品、接受劳务支付的现金 | B12: 356.38 | C12: 628.62 | D12: 817.61 | E12: 213.52 | F12: 563.84 | G12: 829.92 | H12: 1144.84 | I12: 271.99 | J12: 819.77 | K12: 1288.85 | L12: 1274.41 | M12: 565.97 | N12: 1273.1 | O12: 1947.47 | P12: 2866.31 | Q12: 710.75 | R12: 1374.12 | S12: 2076.15 | T12: 2684.36 | U12: 713.02
A13: 支付给职工以及为职工支付的现金 | B13: 28.13 | C13: 38.11 | D13: 53.96 | E13: 15.28 | F13: 34.9 | G13: 51.24 | H13: 75.81 | I13: 19.22 | J13: 41.51 | K13: 64.88 | L13: 91.48 | M13: 22.94 | N13: 47.67 | O13: 80.85 | P13: 117.17 | Q13: 34.46 | R13: 99.1 | S13: 143.19 | T13: 181.7 | U13: 54.28
A14: 支付的各项税费 | B14: 24.01 | C14: 35.82 | D14: 29.48 | E14: 10.6 | F14: 24.74 | G14: 28.94 | H14: 32.29 | I14: 19.89 | J14: 38.92 | K14: 50.02 | L14: 54.17 | M14: 16.79 | N14: 41.12 | O14: 56.34 | P14: 83.72 | Q14: 40.92 | R14: 77.93 | S14: 119 | T14: 145.86 | U14: 48.74
A15: 支付其他与经营活动有关的现金 | B15: 12.7 | C15: 39.81 | D15: 31.98 | E15: 5.67 | F15: 19.73 | G15: 49.29 | H15: 91.9 | I15: 74.79 | J15: 109.52 | K15: 174.59 | L15: 350.63 | M15: 140.35 | N15: 170.93 | O15: 395.92 | P15: 373.13 | Q15: 154.93 | R15: 278.95 | S15: 427.15 | T15: 468.07 | U15: 138.64
A16: 经营活动现金流出(金融类)
A17: 经营活动现金流出差额(特殊报表科目)
A18: 经营活动现金流出差额(合计平衡项目)
A19: 经营活动现金流出小计 | B19: 421.21 | C19: 742.36 | D19: 933.03 | E19: 245.07 | F19: 643.21 | G19: 959.39 | H19: 1344.85 | I19: 385.89 | J19: 1009.71 | K19: 1578.33 | L19: 1770.69 | M19: 746.05 | N19: 1532.82 | O19: 2480.58 | P19: 3440.33 | Q19: 941.05 | R19: 1830.1 | S19: 2765.5 | T19: 3479.99 | U19: 954.67
A20: 经营活动产生的现金流量净额差额(合计平衡项目)
A21: 经营活动产生的现金流量净额 | B21: -99.23 | C21: -195.25 | D21: -286.79 | E21: -33.94 | F21: -202.06 | G21: -176.64 | H21: -234.59 | I21: 58.91 | J21: 1.89 | K21: -26.85 | L21: 62.37 | M21: -187.73 | N21: -345.24 | O21: -642.03 | P21: -841.38 | Q21: -90.49 | R21: -319.66 | S21: -562.11 | T21: -565.85 | U21: 6.15 | V21: 147 | W21: 245.83 | X21: 683.63 | Y21: 252.01 | Z21: 498.61 | AA21: 631.51 | AB21: 595.45 | AC21: 122.44 | AD21: 630.36 | AE21: 1171.19 | AF21: 1619.17 | AG21: 200.99 | AH21: 606.44
A22: 投资活动产生的现金流量：
A23: 收回投资收到的现金 | B23: 180 | C23: 1945.8 | D23: 1262.9 | E23: 453 | F23: 120 | G23: 356 | H23: 1597.5 | I23: 525.5 | J23: 1694.04 | K23: 2586.16 | L23: 2939.83 | M23: 199.66 | N23: 84.65 | O23: 160.62 | P23: 1720.73 | Q23: 60 | R23: 668.39 | S23: 1227.24 | T23: 1702.94 | U23: 1002.37
A24: 取得投资收益收到的现金 | B24: 10.39 | C24: 9.97 | D24: 15.71 | E24: 0.34 | F24: 1.82 | G24: 2.11 | H24: 5.79 | I24: 7.02 | J24: 10.85 | K24: 17.27 | L24: 8.71 | N24: 0.5 | O24: 5.7 | P24: 11.99 | Q24: 2.05 | R24: 0.65 | S24: 1.14 | T24: 8 | U24: 0.08
A25: 处置固定资产、无形资产和其他长期资产收回的现金净额 | C25: 0 | D25: 0.16 | F25: 0 | G25: 0 | H25: 0.01 | I25: 0.19 | J25: 0.06 | K25: 0.06 | L25: 0.06 | N25: 0.26 | O25: 0.31 | P25: 0.31 | Q25: 0.02 | R25: 0.21 | S25: 0.25 | T25: 0.12
A26: 处置子公司及其他营业单位收到的现金净额
A27: 收到其他与投资活动有关的现金 | B27: 12.57 | C27: 12.55 | D27: 16.17 | H27: 2.4 | T27: 1.03
A28: 投资活动现金流入差额(特殊报表科目)
A29: 投资活动现金流入差额(合计平衡项目)
A30: 投资活动现金流入小计 | B30: 202.97 | C30: 1968.32 | D30: 1294.95 | E30: 453.34 | F30: 121.82 | G30: 358.11 | H30: 1605.71 | I30: 532.7 | J30: 1704.95 | K30: 2603.48 | L30: 2948.59 | M30: 199.66 | N30: 85.42 | O30: 166.64 | P30: 1733.03 | Q30: 62.08 | R30: 669.25 | S30: 1228.63 | T30: 1712.09 | U30: 1002.45
A31: 购建固定资产、无形资产和其他长期资产支付的现金 | B31: 30.7 | C31: 62.64 | D31: 72.51 | E31: 8.71 | F31: 20.2 | G31: 37.95 | H31: 81.14 | I31: 14.89 | J31: 31.59 | K31: 43.4 | L31: 82.76 | M31: 26.53 | N31: 63.84 | O31: 119.24 | P31: 115.41 | Q31: 16.92 | R31: 48.78 | S31: 111.08 | T31: 294.36 | U31: 73.02
A32: 投资支付的现金 | C32: 2045.8 | D32: 1082.9 | E32: 580 | F32: 120 | G32: 921 | H32: 2117.5 | I32: 382.36 | J32: 1407.1 | K32: 2294.96 | L32: 2661.58 | M32: 138.97 | N32: 256.03 | O32: 259.35 | P32: 1745.66 | Q32: 15.57 | R32: 808.79 | S32: 1191.3 | T32: 2590.52 | U32: 160.95
A33: 取得子公司及其他营业单位支付的现金净额 | P33: 25.58
A34: 支付其他与投资活动有关的现金 | U34: 2.79
A35: 投资活动现金流出差额(特殊报表科目)
A36: 投资活动现金流出差额(合计平衡项目)
A37: 投资活动现金流出小计 | B37: 30.7 | C37: 2108.44 | D37: 1155.41 | E37: 588.71 | F37: 140.2 | G37: 958.95 | H37: 2198.64 | I37: 397.25 | J37: 1438.69 | K37: 2338.35 | L37: 2744.34 | M37: 165.5 | N37: 319.87 | O37: 378.59 | P37: 1886.65 | Q37: 32.49 | R37: 857.57 | S37: 1302.38 | T37: 2884.88 | U37: 236.77
A38: 投资活动产生的现金流量净额差额(合计平衡项目)
A39: 投资活动产生的现金流量净额 | B39: 172.27 | C39: -140.12 | D39: 139.54 | E39: -135.37 | F39: -18.38 | G39: -600.84 | H39: -592.93 | I39: 135.45 | J39: 266.27 | K39: 265.13 | L39: 204.25 | M39: 34.16 | N39: -234.46 | O39: -211.95 | P39: -153.62 | Q39: 29.59 | R39: -188.32 | S39: -73.75 | T39: -1172.79 | U39: 765.68
A40: 筹资活动产生的现金流量：
...

Sheet 图表5分季度财务数据
A1: 603707.SH
P2: 44742 | Q2: 44834 | R2: 44926 | S2: 45016 | T2: 45107 | U2: 45199 | V2: 45291 | W2: 45382 | X2: 45473 | Y2: 45565 | Z2: 45657 | AA2: 45747 | AB2: 45838 | AC2: 45930 | AD2: 46022 | AE2: 46112 | AF2: 46203
B4: 项目 | C4: 2019-1Q | D4: 2019-2Q | E4: 2019-3Q | F4: 2019-4Q | G4: 2020-1Q | H4: 2020-2Q | I4: 2020-3Q | J4: 2020-4Q | K4: 2021-1Q | L4: 2021-2Q | M4: 2021-3Q | N4: 2021-4Q | O4: 2022-1Q | P4: 2022-2Q | Q4: 2022-3Q | R4: 2022-4Q | S4: 2023-1Q | T4: 2023-2Q | U4: 2023-3Q | V4: 2023-4Q | W4: 2024-1Q | X4: 2024-2Q | Y4: 2024-3Q | Z4: 2024-4Q | AA4: 2025-1Q | AB4: 2025-2Q | AC4: 2025-3Q | AD4: 2025-4Q | AE4: 2026-1Q | AF4: 2026-2Q
B5: 营业收入 | C5: 609.99 | D5: 566.53 | E5: 651.44 | F5: 641.71 | G5: 734.15 | H5: 661.67 | I5: 762.55 | J5: 756.51 | K5: 883.05 | L5: 868.24 | M5: 1028.8 | N5: 906.6 | O5: 1176.56 | P5: =[1]!s_qstm07_is($A$1,"W61445893",P2,1,1000000) -> 798.76269 | Q5: =[1]!s_qstm07_is($A$1,"W61445893",Q2,1,1000000) -> 875.67527 | R5: =[1]!s_qstm07_is($A$1,"W61445893",R2,1,1000000) -> 861.72181 | S5: =[1]!s_qstm07_is($A$1,"W61445893",S2,1,1000000) -> 1307.4826 | T5: =[1]!s_qstm07_is($A$1,"W61445893",T2,1,1000000) -> 996.24993 | U5: =[1]!s_qstm07_is($A$1,"W61445893",U2,1,1000000) -> 838.18544 | V5: =[1]!s_qstm07_is($A$1,"W61445893",V2,1,1000000) -> 789.46927 | W5: =[1]!s_qstm07_is($A$1,"W61445893",W2,1,1000000) -> 1004.2718 | X5: =[1]!s_qstm07_is($A$1,"W61445893",X2,1,1000000) -> 1138.3869 | Y5: 945.35 | Z5: 835.58 | AA5: 885.22 | AB5: 1094.63 | AC5: 945.89 | AD5: 1064.94 | AE5: 928.66 | AF5: 997.6
B6: 营业收入同比 | C6: 0.40021577 | D6: 0.36783524 | E6: 0.43309061 | F6: 0.62072536 | G6: 0.20354432 | H6: 0.16793462 | I6: 0.1705606 | J6: 0.17889701 | K6: 0.20281959 | L6: =L5/H5-1 -> 0.3121949 | M6: =M5/I5-1 -> 0.34915743 | N6: =N5/J5-1 -> 0.19839791 | O6: =O5/K5-1 -> 0.33238208 | P6: =P5/L5-1 -> -0.080020861 | Q6: =Q5/M5-1 -> -0.14883819 | R6: =R5/N5-1 -> -0.049501647 | S6: =S5/O5-1 -> 0.11127578 | ... AF6: =AF5/AB5-1 -> -0.088641824
B7: 营业收入环比 | C7: 0.54061221 | D7: -0.07124707 | E7: 0.14987732 | F7: -0.014936141 | G7: 0.14405261 | H7: -0.098726418 | I7: 0.15246271 | J7: -0.0079207921 | K7: 0.16726811 | L7: =L5/K5-1 -> -0.016771417 | M7: =M5/L5-1 -> 0.18492583 | N7: =N5/M5-1 -> -0.11877916 | O7: =O5/N5-1 -> 0.29777189 | P7: =P5/O5-1 -> -0.32110331 | Q7: =Q5/P5-1 -> 0.096289657 | R7: =R5/Q5-1 -> -0.015934522 | S7: =S5/R5-1 -> 0.51729087 | ... AF7: =AF5/AE5-1 -> 0.074235996
B8: 营业成本 | C8: 320.24 | D8: 267.11 | E8: 311.72 | F8: 305.26 | G8: 325.12 | H8: 229.62 | I8: 321.71 | J8: 319.82 | K8: 374.72 | L8: 370.15 | M8: 450.28 | N8: 400.96 | O8: 582.48 | P8: =[1]!s_qstm07_is($A$1,"W64911286",P2,1,1000000) -> 354.3876 | Q8: =[1]!s_qstm07_is($A$1,"W64911286",Q2,1,1000000) -> 419.20107 | R8: =[1]!s_qstm07_is($A$1,"W64911286",R2,1,1000000) -> 411.92527 | S8: =[1]!s_qstm07_is($A$1,"W64911286",S2,1,1000000) -> 644.97844 | T8: =[1]!s_qstm07_is($A$1,"W64911286",T2,1,1000000) -> 512.26066 | U8: =[1]!s_qstm07_is($A$1,"W64911286",U2,1,1000000) -> 432.62744 | V8: =[1]!s_qstm07_is($A$1,"W64911286",V2,1,1000000) -> 438.85427 | W8: =[1]!s_qstm07_is($A$1,"W64911286",W2,1,1000000) -> 617.68494 | X8: =[1]!s_qstm07_is($A$1,"W64911286",X2,1,1000000) -> 662.86324 | Y8: 528.77 | Z8: 419.05 | AA8: 580.61 | AB8: 657.07 | AC8: 532.98 | AD8: 647.45 | AE8: 628.62 | AF8: 650.65
B9: 毛利率 | C9: =1-C8/C5 -> 0.47500779 | D9: =1-D8/D5 -> 0.5285157 | E9: =1-E8/E5 -> 0.52149085 | F9: =1-F8/F5 -> 0.52430225 | G9: =1-G8/G5 -> 0.55714772 | H9: =1-H8/H5 -> 0.652969 | I9: =1-I8/I5 -> 0.57811291 | J9: =1-J8/J5 -> 0.57724287 | ... AF9: =1-AF8/AF5 -> 0.34778468
B10: 销售费用 | C10: 68.94 | D10: 99.47 | E10: 99.56 | F10: 90.3 | G10: 75.99 | H10: 124.24 | I10: 137.76 | J10: 108.2 | K10: 120.74 | L10: 107.19 | M10: 140.87 | N10: 115.02 | O10: 101.89 | P10: =[1]!s_qstm07_is($A$1,"W67443654",P2,1,1000000) -> 113.56799 | Q10: =[1]!s_qstm07_is($A$1,"W67443654",Q2,1,1000000) -> 135.07847 | R10: =[1]!s_qstm07_is($A$1,"W67443654",R2,1,1000000) -> 101.18377 | S10: =[1]!s_qstm07_is($A$1,"W67443654",S2,1,1000000) -> 120.85036 | T10: =[1]!s_qstm07_is($A$1,"W67443654",T2,1,1000000) -> 140.70509 | U10: =[1]!s_qstm07_is($A$1,"W67443654",U2,1,1000000) -> 47.163069 | V10: =[1]!s_qstm07_is($A$1,"W67443654",V2,1,1000000) -> 111.85378 | W10: =[1]!s_qstm07_is($A$1,"W67443654",W2,1,1000000) -> 65.188546 | X10: =[1]!s_qstm07_is($A$1,"W67443654",X2,1,1000000) -> 77.559926 | Y10: 50.95 | Z10: 86.31 | AA10: 83.79 | AB10: 101.64 | AC10: 99.99 | AD10: 122.81 | AE10: 98.07 | AF10: 105.84
B11: 管理费用 | C11: 7.95 | D11: 8.93 | E11: 9 | F11: 35.14 | G11: 41.85 | H11: 19.47 | I11: 17.39 | J11: 25.18 | K11: 27.05 | L11: 17.79 | M11: 25.72 | N11: 51.67 | O11: 31.29 | P11: =[1]!s_qstm07_is($A$1,"W65221440",P2,1,1000000) -> 33.314531 | Q11: =[1]!s_qstm07_is($A$1,"W65221440",Q2,1,1000000) -> 38.31179 | R11: =[1]!s_qstm07_is($A$1,"W65221440",R2,1,1000000) -> 62.978907 | S11: =[1]!s_qstm07_is($A$1,"W65221440",S2,1,1000000) -> 32.551321 | T11: =[1]!s_qstm07_is($A$1,"W65221440",T2,1,1000000) -> 36.571392 | U11: =[1]!s_qstm07_is($A$1,"W65221440",U2,1,1000000) -> 36.13205 | V11: =[1]!s_qstm07_is($A$1,"W65221440",V2,1,1000000) -> 40.645194 | W11: =[1]!s_qstm07_is($A$1,"W65221440",W2,1,1000000) -> 39.414168 | X11: =[1]!s_qstm07_is($A$1,"W65221440",X2,1,1000000) -> 46.735689 | Y11: 35.08 | Z11: 89.46 | AA11: 42.61 | AB11: 74.97 | AC11: 53.48 | AD11: 71.93 | AE11: 70.4 | AF11: 69.44
B12: 研发费用 | C12: 36.37 | D12: 38.52 | E12: 46.82 | F12: 44.63 | G12: 47.7 | H12: 47.59 | I12: 48.85 | J12: 43.4 | K12: 33.91 | L12: 61.88 | M12: 57.48 | N12: 67.69 | O12: 53.46 | P12: =[1]!s_qstm07_is_103($A$1,P2,1,1000000) -> 52.401332 | Q12: =[1]!s_qstm07_is_103($A$1,Q2,1,1000000) -> 55.658753 | R12: =[1]!s_qstm07_is_103($A$1,R2,1,1000000) -> 102.14154 | S12: =[1]!s_qstm07_is_103($A$1,S2,1,1000000) -> 67.64486 | T12: =[1]!s_qstm07_is_103($A$1,T2,1,1000000) -> 83.16623 | U12: =[1]!s_qstm07_is_103($A$1,U2,1,1000000) -> 61.9925 | V12: =[1]!s_qstm07_is_103($A$1,V2,1,1000000) -> 159.49038 | W12: =[1]!s_qstm07_is_103($A$1,W2,1,1000000) -> 74.90381 | X12: =[1]!s_qstm07_is_103($A$1,X2,1,1000000) -> 99.434401 | Y12: 41.89 | Z12: 113.69 | AA12: 69.24 | AB12: 72.9 | AC12: 118.85 | AD12: 87.14 | AE12: 32.84 | AF12: 86.47
B13: 财务费用 | C13: 0.39 | D13: 0.87 | E13: 4.54 | F13: 10.33 | G13: 9.84 | H13: 9.27 | I13: 17.23 | J13: 21.23 | K13: 10.83 | L13: -15.01 | M13: 8.31 | N13: 68.6 | O13: 10.06 | P13: =[1]!s_qstm07_is($A$1,"W69658192",P2,1,1000000) -> -79.255306 | Q13: =[1]!s_qstm07_is($A$1,"W69658192",Q2,1,1000000) -> -104.66968 | R13: =[1]!s_qstm07_is($A$1,"W69658192",R2,1,1000000) -> 45.364441 | S13: =[1]!s_qstm07_is($A$1,"W69658192",S2,1,1000000) -> 42.984924 | T13: =[1]!s_qstm07_is($A$1,"W69658192",T2,1,1000000) -> -128.68577 | U13: =[1]!s_qstm07_is($A$1,"W69658192",U2,1,1000000) -> 20.651566 | V13: =[1]!s_qstm07_is($A$1,"W69658192",V2,1,1000000) -> -9.1532459 | W13: =[1]!s_qstm07_is($A$1,"W69658192",W2,1,1000000) -> 5.5944726 | X13: =[1]!s_qstm07_is($A$1,"W69658192",X2,1,1000000) -> 10.570127 | Y13: 56.7 | Z13: -63.82 | AA13: 21.8 | AB13: 25.18 | AC13: 32.59 | AD13: 44.55 | AE13: 40.34 | AF13: 23.43
B14: 营业利润 | C14: 169.45 | D14: 151.73 | E14: 177.75 | F14: 168.71 | G14: 234.23 | H14: 223.22 | I14: 214.56 | J14: 204.97 | K14: 303.32 | L14: 321.17 | M14: 339.89 | N14: 217.56 | O14: 388.09 | P14: =[1]!s_qstm07_is($A$1,"W60569001",P2,1,1000000) -> 333.30941 | Q14: =[1]!s_qstm07_is($A$1,"W60569001",Q2,1,1000000) -> 331.58544 | R14: =[1]!s_qstm07_is($A$1,"W60569001",R2,1,1000000) -> 120.56319 | S14: =[1]!s_qstm07_is($A$1,"W60569001",S2,1,1000000) -> 379.4607 | T14: =[1]!s_qstm07_is($A$1,"W60569001",T2,1,1000000) -> 343.61739 | U14: =[1]!s_qstm07_is($A$1,"W60569001",U2,1,1000000) -> 215.94528 | V14: =[1]!s_qstm07_is($A$1,"W60569001",V2,1,1000000) -> -1233.7322 | W14: =[1]!s_qstm07_is($A$1,"W60569001",W2,1,1000000) -> 198.76322 | X14: =[1]!s_qstm07_is($A$1,"W60569001",X2,1,1000000) -> 260.9945 | Y14: 249.49 | Z14: 285.08 | AA14: 92.74 | AB14: 219.21 | AC14: 151.65 | AD14: 237.27 | AE14: 97.71 | AF14: 92.24
B15: 利润总额 | C15: 174.65 | D15: 153.21 | E15: 178.78 | F15: 173.73 | G15: 235.43 | H15: 226.68 | I15: 235.45 | J15: 217.07 | K15: 313.51 | L15: 325.23 | M15: 336.7 | N15: 228.32 | O15: 389.77 | P15: =[1]!s_qstm07_is($A$1,"W67305606",P2,1,1000000) -> 325.65505 | Q15: =[1]!s_qstm07_is($A$1,"W67305606",Q2,1,1000000) -> 334.5915 | R15: =[1]!s_qstm07_is($A$1,"W67305606",R2,1,1000000) -> 135.35544 | S15: =[1]!s_qstm07_is($A$1,"W67305606",S2,1,1000000) -> 381.67216 | T15: =[1]!s_qstm07_is($A$1,"W67305606",T2,1,1000000) -> 356.67679 | U15: =[1]!s_qstm07_is($A$1,"W67305606",U2,1,1000000) -> 218.70205 | V15: =[1]!s_qstm07_is($A$1,"W67305606",V2,1,1000000) -> -1251.8095 | W15: =[1]!s_qstm07_is($A$1,"W67305606",W2,1,1000000) -> 200.49425 | X15: =[1]!s_qstm07_is($A$1,"W67305606",X2,1,1000000) -> 259.17371 | Y15: 247.28 | Z15: 285.09 | AA15: 92.74 | AB15: 217.42 | AC15: 151.93 | AD15: 237.33 | AE15: 97.71 | AF15: 92.23
B16: 所得税 | C16: 25.77 | D16: 12.89 | E16: 19.44 | F16: 16.02 | G16: 31.41 | H16: 23.88 | I16: 33.07 | J16: 29.62 | K16: 40.29 | L16: 44.01 | M16: 45.71 | N16: 9.82 | O16: 59.24 | P16: =[1]!s_qstm07_is($A$1,"W64330616",P2,1,1000000) -> 42.710557 | Q16: =[1]!s_qstm07_is($A$1,"W64330616",Q2,1,1000000) -> 43.216921 | R16: =[1]!s_qstm07_is($A$1,"W64330616",R2,1,1000000) -> -46.318463 | S16: =[1]!s_qstm07_is($A$1,"W64330616",S2,1,1000000) -> 49.344373 | T16: =[1]!s_qstm07_is($A$1,"W64330616",T2,1,1000000) -> 64.490079 | U16: =[1]!s_qstm07_is($A$1,"W64330616",U2,1,1000000) -> 3.8871893 | V16: =[1]!s_qstm07_is($A$1,"W64330616",V2,1,1000000) -> -223.0336 | W16: =[1]!s_qstm07_is($A$1,"W64330616",W2,1,1000000) -> 23.307324 | X16: =[1]!s_qstm07_is($A$1,"W64330616",X2,1,1000000) -> 31.345886 | Y16: 46.52 | Z16: 64.76 | AA16: 8.03 | AB16: 15.87 | AC16: 8.73 | AD16: 85.28 | AE16: 8.69 | AF16: -6.3
B17: 归母净利润 | C17: 148.88 | D17: 140.33 | E17: 159.33 | F17: 156.42 | G17: 204.4 | H17: 204.07 | I17: 204.65 | J17: 193 | K17: 272.9 | L17: 282.62 | M17: 289.18 | N17: 214.6 | O17: 330.09 | P17: =[1]!s_qstm07_is($A$1,"W67788390",P2,1,1000000) -> 283.94639 | Q17: =[1]!s_qstm07_is($A$1,"W67788390",Q2,1,1000000) -> 293.01101 | R17: =[1]!s_qstm07_is($A$1,"W67788390",R2,1,1000000) -> 183.78655 | S17: =[1]!s_qstm07_is($A$1,"W67788390",S2,1,1000000) -> 332.32517 | T17: =[1]!s_qstm07_is($A$1,"W67788390",T2,1,1000000) -> 292.17502 | U17: =[1]!s_qstm07_is($A$1,"W67788390",U2,1,1000000) -> 214.80653 | V17: =[1]!s_qstm07_is($A$1,"W67788390",V2,1,1000000) -> -1028.7525 | W17: =[1]!s_qstm07_is($A$1,"W67788390",W2,1,1000000) -> 177.19031 | X17: =[1]!s_qstm07_is($A$1,"W67788390",X2,1,1000000) -> 227.82728 | Y17: 200.77 | Z17: 220.36 | AA17: 84.71 | AB17: 201.56 | AC17: 143.2 | AD17: 152.07 | AE17: 89.01 | AF17: 98.54
B18: 归母净利润同比 | C18: 0.22383888 | D18: 0.33052053 | E18: 0.48421053 | F18: 0.73626374 | G18: 0.37291779 | H18: 0.45421506 | I18: 0.2844411 | J18: 0.23385756 | K18: 0.3351272 | L18: =L17/H17-1 -> 0.38491694 | M18: =M17/I17-1 -> 0.41304667 | N18: =N17/J17-1 -> 0.1119171 | O18: =O17/K17-1 -> 0.20956394 | P18: =P17/L17-1 -> 0.0046932043 | Q18: =Q17/M17-1 -> 0.013247851 | R18: =R17/N17-1 -> -0.14358552 | S18: =S17/O17-1 -> 0.0067713814 | ... Y18: =Y17/U17-1 -> -0.065345003 | Z18: =-(Z17/V17-1) -> 1.2142012 | AA18: =AA17/W17-1 -> -0.52192644 | AB18: =AB17/X17-1 -> -0.11529473 | AC18: =AC17/Y17-1 -> -0.28674603 | AD18: =AD17/Z17-1 -> -0.30990198 | AE18: =AE17/AA17-1 -> 0.050761421 | AF18: =AF17/AB17-1 -> -0.51111332
B19: 净利率 | C19: =C17/C5 -> 0.24406957 | D19: =D17/D5 -> 0.24770092 | E19: =E17/E5 -> 0.24458124 | F19: =F17/F5 -> 0.24375497 | G19: =G17/G5 -> 0.27841722 | H19: =H17/H5 -> 0.30841658 | I19: =I17/I5 -> 0.26837584 | J19: =J17/J5 -> 0.2551189 | ... AA19: =AA17/AA5 -> 0.095693726 | AB19: 0.1841 | AC19: 0.1514 | AD19: 0.1428 | AE19: 0.0958 | AF19: 0.0988
B20: 扣非归母净利润 | C20: 144.47 | D20: 135.47 | E20: 157.05 | F20: 150.37 | G20: 203.42 | H20: 200.53 | I20: 186.61 | J20: 176.71 | K20: 263.67 | L20: 273.26 | M20: 286.51 | N20: 200.66 | O20: 326.09 | P20: =[1]!s_qfa_deductedprofit($A$1,P2,1000000) -> 289.01911 | Q20: =[1]!s_qfa_deductedprofit($A$1,Q2,1000000) -> 284.45756 | R20: =[1]!s_qfa_deductedprofit($A$1,R2,1000000) -> 180.71259 | S20: =[1]!s_qfa_deductedprofit($A$1,S2,1000000) -> 330.34127 | T20: =[1]!s_qfa_deductedprofit($A$1,T2,1000000) -> 280.98539 | U20: =[1]!s_qfa_deductedprofit($A$1,U2,1000000) -> 211.95512 | V20: =[1]!s_qfa_deductedprofit($A$1,V2,1000000) -> -991.12517 | W20: =[1]!s_qfa_deductedprofit($A$1,W2,1000000) -> 171.37575 | X20: =[1]!s_qfa_deductedprofit($A$1,X2,1000000) -> 197.27602 | Y20: 179.55 | Z20: 233.94 | AA20: 75.32 | AB20: 184.74 | AC20: 123.97 | AD20: 118.69 | AE20: 56.57 | AF20: 89.72
B21: 扣非归母净利润同比 | C21: 0.2528 | D21: 0.3574 | E21: 0.5414 | F21: 0.5971 | G21: 0.4081 | H21: 0.4802 | I21: 0.1882 | J21: 0.1752 | K21: 0.2961 | L21: =L20/H20-1 -> 0.36268887 | M21: =M20/I20-1 -> 0.53534109 | N21: =N20/J20-1 -> 0.13553279 | O21: =O20/K20-1 -> 0.23673531 | P21: =P20/L20-1 -> 0.057670752 | Q21: =Q20/M20-1 -> -0.0071635808 | R21: =R20/N20-1 -> -0.099408997 | S21: =S20/O20-1 -> 0.013037117 | ... Y21: =Y20/U20-1 -> -0.15288671 | Z21: =-(Z20/V20-1) -> 1.2360348 | AA21: =AA20/W20-1 -> -0.5604979 | AB21: =AB20/X20-1 -> -0.063545598 | AC21: =AC20/Y20-1 -> -0.30955166 | AD21: =AD20/Z20-1 -> -0.49264769 | AE21: =AE20/AA20-1 -> -0.24893787 | AF21: =AF20/AB20-1 -> -0.51434448

Sheet 图表6分季度营业收入
E4: 项目 | F4: 2020-1Q | G4: 2020-2Q | H4: 2020-3Q | I4: 2020-4Q | J4: 2021-1Q | K4: 2021-2Q | L4: 2021-3Q | M4: 2021-4Q | N4: 2022-1Q | O4: 2022-2Q | P4: 2022-3Q | Q4: 2022-4Q | R4: 2023-1Q | S4: 2023-2Q | T4: 2023-3Q | U4: 2023-4Q | V4: 2024-1Q | W4: 2024-2Q | X4: 2024-3Q | Y4: 2024-4Q | Z4: 2025-1Q | AA4: 2025-2Q | AB4: 2025-3Q | AC4: 2025-4Q | AD4: 2026-1Q | AE4: 2026-2Q
E5: 营业收入 | F5: =图表5分季度财务数据!G5 -> 734.15 | G5: =图表5分季度财务数据!H5 -> 661.67 | H5: =图表5分季度财务数据!I5 -> 762.55 | I5: =图表5分季度财务数据!J5 -> 756.51 | J5: =图表5分季度财务数据!K5 -> 883.05 | K5: =图表5分季度财务数据!L5 -> 868.24 | L5: =图表5分季度财务数据!M5 -> 1028.8 | M5: =图表5分季度财务数据!N5 -> 906.6 | ... AE5: =图表5分季度财务数据!AF5 -> 997.6
E6: YOY | F6: =图表5分季度财务数据!G6 -> 0.20354432 | G6: =图表5分季度财务数据!H6 -> 0.16793462 | H6: =图表5分季度财务数据!I6 -> 0.1705606 | I6: =图表5分季度财务数据!J6 -> 0.17889701 | J6: =图表5分季度财务数据!K6 -> 0.20281959 | K6: =图表5分季度财务数据!L6 -> 0.3121949 | L6: =图表5分季度财务数据!M6 -> 0.34915743 | M6: =图表5分季度财务数据!N6 -> 0.19839791 | ... AE6: =图表5分季度财务数据!AF6 -> -0.088641824

Sheet 图表7分季度归母净利润
E6: 项目 | F6: 2020-1Q | G6: 2020-2Q | H6: 2020-3Q | I6: 2020-4Q | J6: 2021-1Q | K6: 2021-2Q | L6: 2021-3Q | M6: 2021-4Q | N6: 2022-1Q | O6: 2022-2Q | P6: 2022-3Q | Q6: 2022-4Q | R6: 2023-1Q | S6: 2023-2Q | T6: 2023-3Q | U6: 2023-4Q | V6: 2024-1Q | W6: 2024-2Q | X6: 2024-3Q | Y6: 2024-4Q | Z6: 2025-1Q | AA6: 2025-2Q | AB6: 2025-3Q | AC6: 2025-4Q | AD6: 2026-1Q | AE6: 2026-2Q
E7: 归母净利润 | F7: =图表5分季度财务数据!G17 -> 204.4 | G7: =图表5分季度财务数据!H17 -> 204.07 | H7: =图表5分季度财务数据!I17 -> 204.65 | I7: =图表5分季度财务数据!J17 -> 193 | J7: =图表5分季度财务数据!K17 -> 272.9 | K7: =图表5分季度财务数据!L17 -> 282.62 | L7: =图表5分季度财务数据!M17 -> 289.18 | M7: =图表5分季度财务数据!N17 -> 214.6 | ... AE7: =图表5分季度财务数据!AF17 -> 98.54
E8: YOY | F8: =图表5分季度财务数据!G18 -> 0.37291779 | G8: =图表5分季度财务数据!H18 -> 0.45421506 | H8: =图表5分季度财务数据!I18 -> 0.2844411 | I8: =图表5分季度财务数据!J18 -> 0.23385756 | J8: =图表5分季度财务数据!K18 -> 0.3351272 | K8: =图表5分季度财务数据!L18 -> 0.38491694 | L8: =图表5分季度财务数据!M18 -> 0.41304667 | M8: =图表5分季度财务数据!N18 -> 0.1119171 | ... AE8: =图表5分季度财务数据!AF18 -> -0.51111332
E9: 扣非归母净利润 | F9: =图表5分季度财务数据!G20 -> 203.42 | G9: =图表5分季度财务数据!H20 -> 200.53 | H9: =图表5分季度财务数据!I20 -> 186.61 | I9: =图表5分季度财务数据!J20 -> 176.71 | J9: =图表5分季度财务数据!K20 -> 263.67 | K9: =图表5分季度财务数据!L20 -> 273.26 | L9: =图表5分季度财务数据!M20 -> 286.51 | M9: =图表5分季度财务数据!N20 -> 200.66 | ... AE9: =图表5分季度财务数据!AF20 -> 89.72
E10: YOY | F10: =图表5分季度财务数据!G21 -> 0.4081 | G10: =图表5分季度财务数据!H21 -> 0.4802 | H10: =图表5分季度财务数据!I21 -> 0.1882 | I10: =图表5分季度财务数据!J21 -> 0.1752 | J10: =图表5分季度财务数据!K21 -> 0.2961 | K10: =图表5分季度财务数据!L21 -> 0.36268887 | L10: =图表5分季度财务数据!M21 -> 0.53534109 | M10: =图表5分季度财务数据!N21 -> 0.13553279 | ... AE10: =图表5分季度财务数据!AF21 -> -0.51434448

Sheet 图表8收入拆分
C2: 2018 | D2: 2019 | E2: 2020 | F2: 2021 | G2: 2022 | H2: 2023 | I2: 2024 | K2: 占比 | L2: yoy
B3: 制剂 | C3: 398.42 | D3: 761.91 | E3: 1474.12 | F3: 2130.37 | G3: 2458.17 | H3: 2771.67 | I3: 3050.27 | K3: =I3/$I$7 -> 0.77741813 | L3: =I3/J3-1 -> #DIV/0!
B4: 原料药 | C4: 1183.74 | D4: 1523.87 | E4: 1304.15 | F4: 1427.66 | G4: 1109.64 | H4: 997.33 | I4: 787.14 | K4: =I4/$I$7 -> 0.20061729
B5: CDMO及其他 | C5: 116.46 | D5: 181.53 | E5: 133.05 | F5: 123.42 | G5: 140.3 | H5: 153.74 | I5: 80.32 | K5: =I5/$I$7 -> 0.020471048
B6: 其他业务 | C6: ='图表2-3营业收入和归母净利润'!F3-图表8收入拆分!C3-图表8收入拆分!C4-图表8收入拆分!C5 -> 1.71 | D6: ='图表2-3营业收入和归母净利润'!G3-图表8收入拆分!D3-图表8收入拆分!D4-图表8收入拆分!D5 -> 2.36 | E6: ='图表2-3营业收入和归母净利润'!H3-图表8收入拆分!E3-图表8收入拆分!E4-图表8收入拆分!E5 -> 3.56 | F6: ='图表2-3营业收入和归母净利润'!I3-图表8收入拆分!F3-图表8收入拆分!F4-图表8收入拆分!F5 -> 5.24 | G6: ='图表2-3营业收入和归母净利润'!J3-图表8收入拆分!G3-图表8收入拆分!G4-图表8收入拆分!G5 -> 4.610455 | H6: 8.65 | I6: 5.86 | K6: =I6/$I$7 -> 0.0014935302
B7: total | C7: =SUM(C3:C6) -> 1700.33 | D7: =SUM(D3:D6) -> 2469.67 | E7: =SUM(E3:E6) -> 2914.88 | F7: =SUM(F3:F6) -> 3686.69 | G7: =SUM(G3:G6) -> 3712.7205 | H7: =SUM(H3:H6) -> 3931.39 | I7: =SUM(I3:I6) -> 3923.59
C9: 2018 | D9: 2019 | E9: 2020 | F9: 2021 | G9: 2022 | H9: 2023 | I9: 2024
B10: 制剂 | C10: =C3/C7 -> 0.23431922 | D10: =D3/D7 -> 0.3085068 | E10: =E3/$E$7 -> 0.50572236 | F10: =F3/$F$7 -> 0.57785439 | G10: =G3/$G$7 -> 0.66209402 | H10: =H3/$H$7 -> 0.70501019 | I10: 0.77741813
B11: 原料药 | C11: =C4/C7 -> 0.69618251 | D11: =D4/D7 -> 0.61703385 | E11: =E4/$E$7 -> 0.44741121 | F11: =F4/$F$7 -> 0.3872471 | G11: =G4/$G$7 -> 0.29887518 | H11: =H4/$H$7 -> 0.25368381 | I11: 0.20061729
B12: CDMO及其他 | C12: =C5/C7 -> 0.068492587 | D12: =D5/D7 -> 0.073503747 | E12: =E5/$E$7 -> 0.045645104 | F12: =F5/$F$7 -> 0.033477184 | G12: =G5/$G$7 -> 0.037789002 | H12: =H5/$H$7 -> 0.039105762 | I12: 0.020471048
B13: 其他业务
C17: 2018 | D17: 2019 | E17: 2020 | F17: 2021 | G17: 2022 | H17: 2023 | I17: 2024
B18: 制剂 | C18: =C3 -> 398.42 | D18: =D3 -> 761.91 | E18: =E3 -> 1474.12 | F18: =F3 -> 2130.37 | G18: =G3 -> 2458.17 | H18: 2771.67 | I18: 3050.27
B19: yoy | D19: =D18/C18-1 -> 0.9123287 | E19: =E18/D18-1 -> 0.9347692 | F19: =F18/E18-1 -> 0.44518085 | G19: =G18/F18-1 -> 0.15386999 | H19: =H18/G18-1 -> 0.1275339 | I19: =I18/H18-1 -> 0.10051702
B20: 原料药 | C20: =C4 -> 1183.74 | D20: =D4 -> 1523.87 | E20: =E4 -> 1304.15 | F20: =F4 -> 1427.66 | G20: =G4 -> 1109.64 | H20: 997.33 | I20: 787.14
B21: yoy | D21: =D20/C20-1 -> 0.28733506 | E21: =E20/D20-1 -> -0.14418553 | F21: =F20/E20-1 -> 0.094705364 | G21: =G20/F20-1 -> -0.22275612 | H21: =H20/G20-1 -> -0.10121301 | I21: =I20/H20-1 -> -0.21075271
B22: CDMO及其他 | C22: =C5 -> 116.46 | D22: =D5 -> 181.53 | E22: =E5 -> 133.05 | F22: =F5 -> 123.42 | G22: =G5 -> 140.3 | H22: 153.74 | I22: 80.32
B23: yoy | D23: =D22/C22-1 -> 0.55873261 | E23: =E22/D22-1 -> -0.2670633 | F23: =F22/E22-1 -> -0.072378805 | G23: =G22/F22-1 -> 0.13676876 | H23: =H22/G22-1 -> 0.095794726 | I23: =I22/H22-1 -> -0.47755952
C25: 2022毛利率 | D25: 2023毛利率 | E25: 2024H1 | F25: 24H1YOY
B26: 制剂 | C26: 0.5856 | D26: 0.5451 | E26: 0.441
B27: 标准肝素原料 | C27: 0.4053 | D27: 0.3363 | E27: 0.2903
B28: CDMO及其他 | C28: 0.3864 | D28: 0.3532 | E28: 0.412
B29: 其他业务 | D29: 0.2333 | E29: 0.1647

Sheet 图表9毛利率和净利率
D2: 2016 | E2: 2017 | F2: 2018 | G2: 2019 | H2: 2020 | I2: 2021 | J2: 2022 | K2: 2023 | L2: 2024 | M2: 2025-1Q
C3: 毛利率 | D3: 0.42085546 | E3: 0.46376929 | F3: 0.4946628 | G3: 0.51235185 | H3: 0.58959889 | I3: 0.5671 | J3: 0.5238 | K3: 0.48396821 | L3: 0.4321 | M3: 0.34410655
C4: 净利率 | D4: 0.44206149 | E4: 0.28238656 | F4: 0.24968683 | G4: 0.2449558 | H4: 0.27655341 | I4: 0.2873 | J4: 0.2926 | K4: -0.048188026 | L4: 0.2105 | M4: 0.095693726
L5: =L3-K3 -> -0.051868212
L6: =L4-K4 -> 0.25868803
C22: 分季度
D23: 2020-1Q | E23: 2020-2Q | F23: 2020-3Q | G23: 2020-4Q | H23: 2021-1Q | I23: 2021-2Q | J23: 2021-3Q | K23: 2021-4Q | L23: 2022-1Q | M23: 2022-2Q | N23: 2022-3Q | O23: 2022-4Q | P23: 2023-1Q | Q23: 2023-2Q | R23: 2023-3Q | S23: 2023-4Q | T23: 2024-1Q | U23: 2024-2Q | V23: 2024-3Q | W23: 2024-4Q | X23: 2025-1Q
C24: 毛利率 | D24: 0.55714772 | E24: 0.652969 | F24: 0.57811291 | G24: 0.57724287 | H24: 0.57565257 | I24: =图表5分季度财务数据!L9 -> 0.57367778 | J24: =图表5分季度财务数据!M9 -> 0.56232504 | K24: =图表5分季度财务数据!N9 -> 0.55773219 | L24: =图表5分季度财务数据!O9 -> 0.50492963 | M24: =图表5分季度财务数据!P9 -> 0.5563293 | N24: =图表5分季度财务数据!Q9 -> 0.52128251 | O24: =图表5分季度财务数据!R9 -> 0.52197419 | P24: =图表5分季度财务数据!S9 -> 0.5067021 | ... X24: =图表5分季度财务数据!AA9 -> 0.34410655 | Y24: =X24-T24 -> -0.040835906 | Z24: =X24-W24 -> -0.15438552
C25: 净利率 | D25: 0.27841722 | E25: 0.30841658 | F25: 0.26837584 | G25: 0.2551189 | H25: 0.30904252 | I25: =图表5分季度财务数据!L19 -> 0.32550908 | J25: =图表5分季度财务数据!M19 -> 0.28108476 | K25: =图表5分季度财务数据!N19 -> 0.23670858 | L25: =图表5分季度财务数据!O19 -> 0.28055518 | M25: =图表5分季度财务数据!P19 -> 0.3554828 | N25: =图表5分季度财务数据!Q19 -> 0.3346115 | O25: =图表5分季度财务数据!R19 -> 0.21327828 | P25: =图表5分季度财务数据!S19 -> 0.25417176 | ... X25: =图表5分季度财务数据!AA19 -> 0.095693726 | Y25: =X25-T25 -> -0.080742881 | Z25: =X25-W25 -> -0.16802728

Sheet 图表10研发费用
D2: 2016 | E2: 2017 | F2: 2018 | G2: 2019 | H2: 2020 | I2: 2021 | J2: 2022 | K2: 2023 | L2: 2024 | M2: 2025 | N2: 2026H1 | O2: 2025H1
C3: 研发费用 | D3: 49.047849 | E3: 77.185185 | F3: 101.18 | G3: 166.35 | H3: 187.53 | I3: 220.95 | J3: 263.66 | K3: 372.29397 | L3: 329.92 | M3: 348.13 | N3: 119.31 | O3: 142.14
C4: 研发费用率 | D4: =D3/'图表2-3营业收入和归母净利润'!D3 -> 0.084287689 | E4: =E3/'图表2-3营业收入和归母净利润'!E3 -> 0.069365601 | F4: =F3/'图表2-3营业收入和归母净利润'!F3 -> 0.059506096 | G4: =G3/'图表2-3营业收入和归母净利润'!G3 -> 0.067357177 | H4: =H3/'图表2-3营业收入和归母净利润'!H3 -> 0.06433541 | I4: =I3/'图表2-3营业收入和归母净利润'!I3 -> 0.059931809 | J4: 0.071 | K4: 0.094697863 | L4: =L3/L5 -> 0.084086258 | M4: =M3/M5 -> 0.087235759 | N4: =N3/N5 -> 0.061938679 | O4: =O3/O5 -> 0.071793318
C5: 营业收入 | L5: 3923.59 | M5: 3990.68 | N5: 1926.26 | O5: 1979.85
E26: 项目 | F26: 2022-4Q | G26: 2023-1Q | H26: 2023-2Q | I26: 2023-3Q | J26: 2023-4Q | K26: 2024-1Q | L26: 2024-2Q | M26: 2024-3Q | N26: 2024-4Q | O26: 2025-1Q | P26: 2025-2Q | Q26: 2025-3Q | R26: 2025-4Q | S26: 2026-1Q | T26: 2026-2Q
E27: 营业收入 | F27: 861.72181 | G27: 1307.4826 | H27: 996.24993 | I27: 838.18544 | J27: 789.46927 | K27: 1004.2718 | L27: 1138.3869 | M27: =图表5分季度财务数据!Y5 -> 945.35 | N27: =图表5分季度财务数据!Z5 -> 835.58 | O27: =图表5分季度财务数据!AA5 -> 885.22 | P27: =图表5分季度财务数据!AB5 -> 1094.63 | Q27: =图表5分季度财务数据!AC5 -> 945.89 | R27: =图表5分季度财务数据!AD5 -> 1064.94 | S27: =图表5分季度财务数据!AE5 -> 928.66 | T27: =图表5分季度财务数据!AF5 -> 997.6
E28: 研发费用 | F28: 102.14154 | G28: 67.64486 | H28: 83.16623 | I28: 61.9925 | J28: 159.49038 | K28: 74.90381 | L28: 99.434401 | M28: =图表5分季度财务数据!Y12 -> 41.89 | N28: =图表5分季度财务数据!Z12 -> 113.69 | O28: =图表5分季度财务数据!AA12 -> 69.24 | P28: =图表5分季度财务数据!AB12 -> 72.9 | Q28: =图表5分季度财务数据!AC12 -> 118.85 | R28: =图表5分季度财务数据!AD12 -> 87.14 | S28: =图表5分季度财务数据!AE12 -> 32.84 | T28: =图表5分季度财务数据!AF12 -> 86.47
E29: 研发费用率 | F29: =F28/F27 -> 0.11853192 | G29: =G28/G27 -> 0.051736718 | H29: =H28/H27 -> 0.083479283 | I29: =I28/I27 -> 0.073960363 | J29: =J28/J27 -> 0.20202228 | K29: =K28/K27 -> 0.074585198 | L29: =L28/L27 -> 0.087346751 | M29: =M28/M27 -> 0.044311631 | ... T29: =T28/T27 -> 0.086678027

Sheet 图表11期间费用率
D2: 2016 | E2: 2017 | F2: 2018 | G2: 2019 | H2: 2020 | I2: 2021 | J2: 2022 | K2: 2023 | L2: 2024 | M2: 2025 | N2: 26H1 | O2: 25H1 | P2: H1YOY | Q2: 25YOY%
C3: 销售费用率 | D3: 0.017116049 | E3: 0.042211498 | F3: 0.14566584 | G3: 0.14507201 | H3: 0.1530732 | I3: 0.1312 | J3: 0.1217 | K3: 0.10697809 | L3: 0.0714 | M3: 0.1023 | N3: 0.1059 | O3: 0.0937 | P3: =N3-O3 -> 0.0122 | Q3: =M3-L3 -> 0.0309
C4: 管理费用率 | D4: 0.061490868 | E4: 0.041146383 | F4: 0.059506096 | G4: 0.067357177 | H4: 0.06433541 | I4: 0.0332 | J4: 0.0447 | K4: 0.037111571 | L4: 0.0537 | M4: 0.0609 | N4: 0.0726 | O4: 0.0594 | P4: =N4-O4 -> 0.0132 | Q4: =M4-L4 -> 0.0072
C5: 财务费用率 | D5: 0.00070457631 | E5: -0.0039003172 | F5: -0.00018231755 | G5: 0.006531237 | H5: 0.019750384 | I5: 0.0197 | J5: -0.0346 | K5: -0.018874386 | L5: 0.0023 | M5: 0.0311 | N5: 0.0331 | O5: 0.0237 | P5: =N5-O5 -> 0.0094 | Q5: =M5-L5 -> 0.0288
C6: 期间费用率 | D6: =SUM(D3:D5) -> 0.079311493 | E6: =SUM(E3:E5) -> 0.079457564 | F6: =SUM(F3:F5) -> 0.20498962 | G6: =SUM(G3:G5) -> 0.21896043 | H6: =SUM(H3:H5) -> 0.23715899 | I6: =SUM(I3:I5) -> 0.1841 | J6: =SUM(J3:J5) -> 0.1318 | K6: 0.12521528 | L6: =SUM(L3:L5) -> 0.1274 | M6: =SUM(M3:M5) -> 0.1943 | N6: 0.2116 | O6: 0.1768 | P6: =N6-O6 -> 0.0348 | Q6: =M6-L6 -> 0.0669
C7: 营业收入 | M7: 3990.68 | N7: 1926.26 | O7: 1979.85
C8: 销售费用 | M8: 408.23 | N8: 203.91 | O8: 185.43
C9: 管理费用 | M9: 242.99 | N9: 139.84 | O9: 117.58
C10: 财务费用 | M10: 124.12 | N10: 63.77 | O10: 46.98
C11: 期间费用 | M11: 775.34 | N11: 407.52 | O11: 349.99
A24: 分季度三项费用率
B25: 2020-1Q | C25: 2020-2Q | D25: 2020-3Q | E25: 2020-4Q | F25: 2021-1Q | G25: 2021-2Q | H25: 2021-3Q | I25: 2021-4Q | J25: 2022-1Q | K25: 2022-2Q | L25: 2022-3Q | M25: 2022-4Q | N25: 2023-1Q | O25: 2023-2Q | P25: 2023-3Q | Q25: 2023-4Q | R25: 2024-1Q | S25: 2024-2Q | T25: 2024-3Q | U25: 2024-4Q | V25: 2025-1Q | W25: 2025-2Q | X25: 2025-3Q | Y25: 2025-4Q | Z25: 2026-1Q | AA25: 2026-2Q
A26: 销售费用率 | B26: 0.10350746 | C26: 0.18776732 | D26: 0.18065701 | E26: 0.14302521 | F26: 0.13673065 | G26: =图表5分季度财务数据!L10/图表5分季度财务数据!L5 -> 0.12345665 | H26: =图表5分季度财务数据!M10/图表5分季度财务数据!M5 -> 0.13692652 | I26: =图表5分季度财务数据!N10/图表5分季度财务数据!N5 -> 0.12686962 | J26: =图表5分季度财务数据!O10/图表5分季度财务数据!O5 -> 0.086599918 | K26: =图表5分季度财务数据!P10/图表5分季度财务数据!P5 -> 0.14217989 | L26: =图表5分季度财务数据!Q10/图表5分季度财务数据!Q5 -> 0.15425635 | M26: =图表5分季度财务数据!R10/图表5分季度财务数据!R5 -> 0.11742046 | N26: =图表5分季度财务数据!S10/图表5分季度财务数据!S5 -> 0.0924298 | ... AA26: =图表5分季度财务数据!AF10/图表5分季度财务数据!AF5 -> 0.10609463
A27: 管理费用率 | B27: 0.057004699 | C27: 0.029425544 | D27: 0.022805062 | E27: 0.033284425 | F27: 0.030632467 | G27: =图表5分季度财务数据!L11/图表5分季度财务数据!L5 -> 0.020489726 | H27: =图表5分季度财务数据!M11/图表5分季度财务数据!M5 -> 0.025 | I27: =图表5分季度财务数据!N11/图表5分季度财务数据!N5 -> 0.056993161 | J27: =图表5分季度财务数据!O11/图表5分季度财务数据!O5 -> 0.026594479 | K27: =图表5分季度财务数据!P11/图表5分季度财务数据!P5 -> 0.04170767 | L27: =图表5分季度财务数据!Q11/图表5分季度财务数据!Q5 -> 0.043751138 | M27: =图表5分季度财务数据!R11/图表5分季度财务数据!R5 -> 0.073084964 | N27: =图表5分季度财务数据!S11/图表5分季度财务数据!S5 -> 0.024896179 | ... AA27: =图表5分季度财务数据!AF11/图表5分季度财务数据!AF5 -> 0.069607057
A28: 财务费用率 | B28: 0.013403255 | C28: 0.014010005 | D28: 0.02259524 | E28: 0.028063079 | F28: 0.012264311 | G28: =图表5分季度财务数据!L13/图表5分季度财务数据!L5 -> -0.017287847 | H28: =图表5分季度财务数据!M13/图表5分季度财务数据!M5 -> 0.0080773717 | I28: =图表5分季度财务数据!N13/图表5分季度财务数据!N5 -> 0.075667328 | J28: =图表5分季度财务数据!O13/图表5分季度财务数据!O5 -> 0.0085503502 | K28: =图表5分季度财务数据!P13/图表5分季度财务数据!P5 -> -0.099222594 | L28: =图表5分季度财务数据!Q13/图表5分季度财务数据!Q5 -> -0.11953025 | M28: =图表5分季度财务数据!R13/图表5分季度财务数据!R5 -> 0.052643952 | N28: =图表5分季度财务数据!S13/图表5分季度财务数据!S5 -> 0.032876096 | ... AA28: =图表5分季度财务数据!AF13/图表5分季度财务数据!AF5 -> 0.023486367
A29: 期间费用率 | B29: =SUM(B26:B28) -> 0.17391541 | C29: =SUM(C26:C28) -> 0.23120287 | D29: =SUM(D26:D28) -> 0.22605731 | E29: =SUM(E26:E28) -> 0.20437271 | F29: =SUM(F26:F28) -> 0.17962743 | G29: =SUM(G26:G28) -> 0.12665853 | H29: =SUM(H26:H28) -> 0.17000389 | I29: =SUM(I26:I28) -> 0.25953011 | ... AA29: =SUM(AA26:AA28) -> 0.19918805

Sheet 毛利率
A1: 2024 | B1: 2025 | C1: 2026Q2 | D1: 2025Q2 | E1: yOY2025 | F1: YOY26Q2
A2: 0.4321 | B2: 0.3941 | C2: 0.3478 | D2: 0.3997 | E2: =B2-A2 -> -0.038 | F2: =C2-D2 -> -0.0519

Sheet 图表12ANDA_20230227
A1: 市场状态 | B1: 活性成分 | C1: 中文名 | D1: ANDA文号 | E1: 剂型 | F1: 持证商 | G1: 获批日期
C2: 注射用盐酸吉西他滨
C3: 罗库溴铵注射液 | G3: 45047
C4: 注射用盐酸苯达莫司汀 | G4: 45078
C5: 唑来膦酸注射液 | G5: 45078
C6: 盐酸布比卡因注射液(MDV) | G6: 45078
C7: 注射用亚叶酸钙 | G7: 45108
C8: 普乐沙福注射液 | G8: 45108
C9: 依诺肝素钠注射液 | G9: 45108
C10: 盐酸帕洛诺司琼注射液 | G10: 45139
C11: 注射用米卡芬净钠 | G11: 45261
C12: 盐酸布比卡因注射液(SDV) | G12: 45261
C13: 注射用塞替派 | G13: 45261
A14: RX | B14: NELARABINE | C14: 奈拉滨 | D14: A216038 | E14: 250MG/50ML (5MG/ML) | F14: KINDOS PHARMACEUTICALS CO LTD | G14: 44936
A15: RX | B15: PLERIXAFOR | C15: 普乐沙福 | D15: A215698 | E15: 24 mg/1.2 Ml | G15: 44911
A16: RX | B16: PEMETREXED DISODIUM | C16: 培美曲塞二钠 | D16: A215479 | E16: EQ 100MG BASE/VIAL | F16: MEITHEAL PHARMACEUTICALS INC | G16: 44908
A17: RX | B17: PEMETREXED DISODIUM | C17: 培美曲塞二钠 | D17: A215479 | E17: EQ 500MG BASE/VIAL | F17: MEITHEAL PHARMACEUTICALS INC | G17: 44908
A18: RX | B18: PEMETREXED DISODIUM | C18: 培美曲塞二钠 | D18: A215479 | E18: EQ 750MG BASE/VIAL | F18: MEITHEAL PHARMACEUTICALS INC | G18: 44908
A19: RX | B19: PEMETREXED DISODIUM | C19: 培美曲塞二钠 | D19: A215479 | E19: EQ 1GM BASE/VIAL | F19: MEITHEAL PHARMACEUTICALS INC | G19: 44908
A20: RX | B20: MICAFUNGIN SODIUM | C20: 米卡芬净 | D20: A215381 | E20: EQ 100MG BASE/VIAL | F20: MEITHEAL PHARMACEUTICALS INC | G20: 44832
A21: RX | B21: MITOMYCIN | C21: 丝裂霉素 | D21: A214505 | E21: 5MG/VIAL | F21: MEITHEAL PHARMACEUTICALS INC | G21: 44812
A22: RX | B22: PANTOPRAZOLE SODIUM | C22: 泮托拉唑钠 | D22: A215860 | E22: EQ 40MG BASE/VIAL | F22: MEITHEAL PHARMACEUTICALS INC | G22: 44802
A23: RX | B23: VANCOMYCIN HYDROCHLORIDE | C23: 盐酸万古霉素 | D23: A215196 | E23: EQ 500MG BASE/VIAL | F23: Nanjing King-Friend（母公司） | G23: 44770
A24: RX | B24: VANCOMYCIN HYDROCHLORIDE | C24: 盐酸万古霉素 | D24: A215196 | E24: EQ 1GM BASE/VIAL | F24: Nanjing King-Friend（母公司） | G24: 44770
A25: RX | B25: VANCOMYCIN HYDROCHLORIDE | C25: 盐酸万古霉素 | D25: A215196 | E25: EQ 5GM BASE/VIAL | F25: Nanjing King-Friend（母公司） | G25: 44769
A26: RX | B26: VANCOMYCIN HYDROCHLORIDE | C26: 盐酸万古霉素 | D26: A215196 | E26: EQ 10GM BASE/VIAL | F26: Nanjing King-Friend（母公司） | G26: 44769
A27: RX | B27: BORTEZOMIB | C27: 硼替佐米 | D27: A212958 | E27: 3.5MG/VIAL | F27: KINDOS（子公司） | G27: 44748
... A55: RX | B55: Busulfan | C55: 白消安 | D55: A212127 | E55: 6MG/ML | F55: Meitheal（子公司） | G55: 44127
A56: TA | B56: Bendamustine Hydrochloride | C56: 苯达莫司汀 | D56: A211001 | E56: UNKNOWN | F56: Nanjing King-Friend（母公司） | G56: 2020/4/21(TA) | I56: =PROPER(B56) -> Bendamustine Hydrochloride
A57: TA | B57: Bortezomib | C57: 硼替佐米 | D57: A212958 | E57: UNKNOWN | F57: Nanjing King-Friend（母公司） | G57: 2020/3/20(TA) | I57: =PROPER(B57) -> Bortezomib
A58: RX | B58: Milrinone Lactate | C58: 乳酸米力农 | D58: A211671 | E58: EQ 1MG BASE/ML | F58: Meitheal（子公司） | G58: 43914
A59: RX | B59: Doxercalciferol | C59: 度骨化醇 | D59: A211670 | E59: 4MCG/2ML (2MCG/ML) | F59: Meitheal（子公司） | G59: 43868
A60: RX | B60: Enoxaparin Sodium | C60: 依诺肝素钠 | D60: A206834 | E60: 30MG/0.3ML (100MG/ML) | F60: Nanjing King-Friend（母公司） | G60: 43798
A61: RX | B61: Enoxaparin Sodium | C61: 依诺肝素钠 | D61: A206834 | E61: 40MG/0.4ML (100MG/ML) | F61: Nanjing King-Friend（母公司） | G61: 43798
A62: RX | B62: Enoxaparin Sodium | C62: 依诺肝素钠 | D62: A206834 | E62: 60MG/0.6ML (100MG/ML) | F62: Nanjing King-Friend（母公司） | G62: 43798
A63: RX | B63: Enoxaparin Sodium | C63: 依诺肝素钠 | D63: A206834 | E63: 80MG/0.8ML (100MG/ML) | F63: Nanjing King-Friend（母公司） | G63: 43798
A64: RX | B64: Enoxaparin Sodium | C64: 依诺肝素钠 | D64: A206834 | E64: 100MG/ML (100MG/ML) | F64: Nanjing King-Friend（母公司） | G64: 43798
A65: RX | B65: Enoxaparin Sodium | C65: 依诺肝素钠 | D65: A206834 | E65: 120MG/0.8ML (150MG/ML) | F65: Nanjing King-Friend（母公司） | G65: 43798
A66: RX | B66: Enoxaparin Sodium | C66: 依诺肝素钠 | D66: A206834 | E66: 150MG/ML (150MG/ML) | F66: Nanjing King-Friend（母公司） | G66: 43798
A67: RX | B67: Sodium Nitroprusside | C67: 硝普钠 | D67: A211016 | E67: 25MG/ML | F67: Hong Kong King Friend（子公司） | G67: 43798
...

Sheet 图表12ANDA
A1: 市场状态 | B1: 活性成分 | C1: 中文名 | D1: ANDA文号 | E1: 剂型 | F1: 持证商 | G1: 获批日期
A2: RX | B2: DACARBAZINE | C2: 注射用达卡巴嗪 | D2: A075371 | E2: 100MG/VIAL | F2: FRESENIUS KABI USA LLC | G2: 45444
A3: RX | B3: DACARBAZINE | C3: 注射用达卡巴嗪 | D3: A075371 | E3: 200MG/VIAL | F3: FRESENIUS KABI USA LLC | G3: 45444
A4: RX | B4: DACARBAZINE | C4: 注射用达卡巴嗪 | D4: A075812 | E4: 200MG/VIAL | F4: HIKMA PHARMACEUTICALS USA INC | G4: 45444
A5: RX | B5: DACARBAZINE | C5: 注射用达卡巴嗪 | D5: A075940 | E5: 200MG/VIAL | F5: HOSPIRA INC | G5: 45444
A6: RX | B6: DACARBAZINE | C6: 注射用达卡巴嗪 | D6: A075259 | E6: 200MG/VIAL | F6: MEITHEAL PHARMACEUTICALS INC | G6: 45444
A7: RX | B7: DACARBAZINE | C7: 注射用达卡巴嗪 | D7: A075812 | E7: 500MG/VIAL | F7: HIKMA PHARMACEUTICALS USA INC | G7: 45444
A8: RX | B8: DACARBAZINE | C8: 注射用达卡巴嗪 | D8: A075259 | E8: 500MG/VIAL | F8: MEITHEAL PHARMACEUTICALS INC | G8: 45444
A9: RX | B9: THIOTEPA | C9: 注射用塞替派 | D9: A211831 | E9: 15MG/VIAL | F9: BELOTECA INC | G9: 45267
A10: RX | B10: THIOTEPA | C10: 注射用塞替派 | D10: A210337 | E10: 15MG/VIAL | F10: DR REDDYS LABORATORIES LTD | G10: 45267
A11: RX | B11: THIOTEPA | C11: 注射用塞替派 | D11: A209150 | E11: 15MG/VIAL | F11: JIANGSU HENGRUI PHARMACEUTICALS CO LTD | G11: 45267
A12: RX | B12: THIOTEPA | C12: 注射用塞替派 | D12: A208242 | E12: 15MG/VIAL | F12: PENN LIFE SCIENCES LLC | G12: 45267
A13: RX | B13: THIOTEPA | C13: 注射用塞替派 | D13: A075547 | E13: 15MG/VIAL | F13: WEST-WARD PHARMACEUTICALS INTERNATIONAL LTD | G13: 45267
... A37: RX | B37: NELARABINE | C37: 奈拉滨 | D37: A216038 | E37: 250MG/50ML (5MG/ML) | F37: KINDOS PHARMACEUTICALS CO LTD | G37: 44936
A38: RX | B38: PLERIXAFOR | C38: 普乐沙福 | D38: A215698 | E38: 24 mg/1.2 Ml | G38: 44911
A39: RX | B39: PEMETREXED DISODIUM | C39: 培美曲塞二钠 | D39: A215479 | E39: EQ 100MG BASE/VIAL | F39: MEITHEAL PHARMACEUTICALS INC | G39: 44908
A40: RX | B40: PEMETREXED DISODIUM | C40: 培美曲塞二钠 | D40: A215479 | E40: EQ 500MG BASE/VIAL | F40: MEITHEAL PHARMACEUTICALS INC | G40: 44908
A41: RX | B41: PEMETREXED DISODIUM | C41: 培美曲塞二钠 | D41: A215479 | E41: EQ 750MG BASE/VIAL | F41: MEITHEAL PHARMACEUTICALS INC | G41: 44908
A42: RX | B42: PEMETREXED DISODIUM | C42: 培美曲塞二钠 | D42: A215479 | E42: EQ 1GM BASE/VIAL | F42: MEITHEAL PHARMACEUTICALS INC | G42: 44908
A43: RX | B43: MICAFUNGIN SODIUM | C43: 米卡芬净 | D43: A215381 | E43: EQ 100MG BASE/VIAL | F43: MEITHEAL PHARMACEUTICALS INC | G43: 44832
A44: RX | B44: MITOMYCIN | C44: 丝裂霉素 | D44: A214505 | E44: 5MG/VIAL | F44: MEITHEAL PHARMACEUTICALS INC | G44: 44812
A45: RX | B45: PANTOPRAZOLE SODIUM | C45: 泮托拉唑钠 | D45: A215860 | E45: EQ 40MG BASE/VIAL | F45: MEITHEAL PHARMACEUTICALS INC | G45: 44802
A46: RX | B46: VANCOMYCIN HYDROCHLORIDE | C46: 盐酸万古霉素 | D46: A215196 | E46: EQ 500MG BASE/VIAL | F46: Nanjing King-Friend（母公司） | G46: 44770
A47: RX | B47: VANCOMYCIN HYDROCHLORIDE | C47: 盐酸万古霉素 | D47: A215196 | E47: EQ 1GM BASE/VIAL | F47: Nanjing King-Friend（母公司） | G47: 44770
A48: RX | B48: VANCOMYCIN HYDROCHLORIDE | C48: 盐酸万古霉素 | D48: A215196 | E48: EQ 5GM BASE/VIAL | F48: Nanjing King-Friend（母公司） | G48: 44769
A49: RX | B49: VANCOMYCIN HYDROCHLORIDE | C49: 盐酸万古霉素 | D49: A215196 | E49: EQ 10GM BASE/VIAL | F49: Nanjing King-Friend（母公司） | G49: 44769
A50: RX | B50: BORTEZOMIB | C50: 硼替佐米 | D50: A212958 | E50: 3.5MG/VIAL | F50: KINDOS（子公司） | G50: 44748
... A78: RX | B78: Busulfan | C78: 白消安 | D78: A212127 | E78: 6MG/ML | F78: Meitheal（子公司） | G78: 44127
A79: TA | B79: Bendamustine Hydrochloride | C79: 苯达莫司汀 | D79: A211001 | E79: UNKNOWN | F79: Nanjing King-Friend（母公司） | G79: 2020/4/21(TA)
A80: TA | B80: Bortezomib | C80: 硼替佐米 | D80: A212958 | E80: UNKNOWN | F80: Nanjing King-Friend（母公司） | G80: 2020/3/20(TA)
A81: RX | B81: Milrinone Lactate | C81: 乳酸米力农 | D81: A211671 | E81: EQ 1MG BASE/ML | F81: Meitheal（子公司） | G81: 43914
A82: RX | B82: Doxercalciferol | C82: 度骨化醇 | D82: A211670 | E82: 4MCG/2ML (2MCG/ML) | F82: Meitheal（子公司） | G82: 43868
A83: RX | B83: Enoxaparin Sodium | C83: 依诺肝素钠 | D83: A206834 | E83: 30MG/0.3ML (100MG/ML) | F83: Nanjing King-Friend（母公司） | G83: 43798
A84: RX | B84: Enoxaparin Sodium | C84: 依诺肝素钠 | D84: A206834 | E84: 40MG/0.4ML (100MG/ML) | F84: Nanjing King-Friend（母公司） | G84: 43798
A85: RX | B85: Enoxaparin Sodium | C85: 依诺肝素钠 | D85: A206834 | E85: 60MG/0.6ML (100MG/ML) | F85: Nanjing King-Friend（母公司） | G85: 43798
A86: RX | B86: Enoxaparin Sodium | C86: 依诺肝素钠 | D86: A206834 | E86: 80MG/0.8ML (100MG/ML) | F86: Nanjing King-Friend（母公司） | G86: 43798
A87: RX | B87: Enoxaparin Sodium | C87: 依诺肝素钠 | D87: A206834 | E87: 100MG/ML (100MG/ML) | F87: Nanjing King-Friend（母公司） | G87: 43798
A88: RX | B88: Enoxaparin Sodium | C88: 依诺肝素钠 | D88: A206834 | E88: 120MG/0.8ML (150MG/ML) | F88: Nanjing King-Friend（母公司） | G88: 43798
A89: RX | B89: Enoxaparin Sodium | C89: 依诺肝素钠 | D89: A206834 | E89: 150MG/ML (150MG/ML) | F89: Nanjing King-Friend（母公司） | G89: 43798
A90: RX | B90: Sodium Nitroprusside | C90: 硝普钠 | D90: A211016 | E90: 25MG/ML | F90: Hong Kong King Friend（子公司） | G90: 43798
...

Sheet Sheet3
A1: RX | B1: THIOTEPA | C1: 注射用塞替派 | D1: A211831 | E1: 15MG/VIAL | F1: BELOTECA INC | G1: 45267
A2: RX | B2: THIOTEPA | C2: 注射用塞替派 | D2: A210337 | E2: 15MG/VIAL | F2: DR REDDYS LABORATORIES LTD | G2: 45267
A3: RX | B3: THIOTEPA | C3: 注射用塞替派 | D3: A209150 | E3: 15MG/VIAL | F3: JIANGSU HENGRUI PHARMACEUTICALS CO LTD | G3: 45267
A4: RX | B4: THIOTEPA | C4: 注射用塞替派 | D4: A208242 | E4: 15MG/VIAL | F4: PENN LIFE SCIENCES LLC | G4: 45267
A5: RX | B5: THIOTEPA | C5: 注射用塞替派 | D5: A075547 | E5: 15MG/VIAL | F5: WEST-WARD PHARMACEUTICALS INTERNATIONAL LTD | G5: 45267
A6: RX | B6: THIOTEPA | C6: 注射用塞替派 | D6: N208264 | E6: 15MG/VIAL | F6: ADIENNE SA | G6: 45267
A7: RX | B7: THIOTEPA | C7: 注射用塞替派 | D7: N208264 | E7: 100MG/VIAL | F7: ADIENNE SA | G7: 45267
A8: RX | B8: THIOTEPA | C8: 注射用塞替派 | D8: A214222 | E8: 15MG/VIAL | F8: GLAND PHARMA LTD | G8: 45267
A9: RX | B9: THIOTEPA | C9: 注射用塞替派 | D9: A216037 | E9: 15MG/VIAL | F9: KINDOS PHARMACEUTICALS CO LTD | G9: 45267
A10: RX | B10: THIOTEPA | C10: 注射用塞替派 | D10: A213049 | E10: 15MG/VIAL | F10: MSN LABORATORIES PRIVATE LTD | G10: 45267
A11: RX | B11: THIOTEPA | C11: 注射用塞替派 | D11: A214222 | E11: 100MG/VIAL | F11: GLAND PHARMA LTD | G11: 45267
A12: RX | B12: THIOTEPA | C12: 注射用塞替派 | D12: A211755 | E12: 100MG/VIAL | F12: HIKMA PHARMACEUTICALS USA INC | G12: 45267
... A29: RX | B29: NELARABINE | C29: 奈拉滨 | D29: A216038 | E29: 250MG/50ML (5MG/ML) | F29: KINDOS PHARMACEUTICALS CO LTD | G29: 44936
